DEBUG: Executing python function do_clean
ERROR: Error executing a python function in exec_func_python() autogenerated:

The stack trace of python calls that resulted in this exception/failure was:
File: 'exec_func_python() autogenerated', lineno: 2, function: <module>
     0001:
 *** 0002:do_clean(d)
     0003:
File: '/home/abdelaziz/mylayer/printhello.bb', lineno: 16, function: do_clean
     0012:
     0013:python do_clean() {
     0014:
     0015:    import os
 *** 0016:    os.remove("/home/abdelaziz/hello/tmp")
     0017:
     0018:}
     0019:
     0020:
Exception: IsADirectoryError: [Errno 21] Is a directory: '/home/abdelaziz/hello/tmp'

DEBUG: Python function do_clean finished
